Workbook
Name ABC: #REF!
Name scn_A_cogs_up: Scenario_Analysis!$Y$2
Name scn_B_returns_up: Scenario_Analysis!$Y$3
Name scn_C_price_down: Scenario_Analysis!$Y$4

Sheet Raw_Data
A2: sku_rank | B2: product_id | C2: category | D2: units_sold | E2: order_count | F2: gross_revenue | G2: cogs | H2: storage_cost | I2: fulfillment_cost | J2: freight_cost | K2: return_loss | L2: total_cost_sql_check | M2: net_profit_sql_check | N2: net_margin_pct_sql_check | O2: avg_review_score | P2: decision
A3: 1 | B3: bb50f2e236e5eea0100680137654686c | C3: health_beauty | D3: 195 | E3: 187 | F3: 63885 | G3: 26831.7 | H3: 195 | I3: 748 | J3: 3721.1 | K3: 70.2 | L3: 31566 | M3: 32319 | N3: 0.5059 | O3: 4.22 | P3: SCALE
A4: 2 | B4: 6cdd53843498f92890544667809f1595 | C4: health_beauty | D4: 156 | E4: 151 | F4: 54730.2 | G4: 22986.68 | H4: 156 | I4: 604 | J4: 4363.79 | K4: 56.16 | L4: 28166.63 | M4: 26563.57 | N4: 0.4854 | O4: 4.32 | P4: SCALE
A5: 3 | B5: d6160fb7873f184099d9bc95e30376af | C5: computers | D5: 35 | E5: 35 | F5: 48899.34 | G5: 27872.62 | H5: 78.75 | I5: 350 | J5: 1426.84 | K5: 31.5 | L5: 29759.71 | M5: 19139.63 | N5: 0.3914 | O5: 4.57 | P5: SCALE
A6: 4 | B6: d1c427060a0f73f6b889a5c7c61f2ac4 | C6: computers_accessories | D6: 341 | E6: 321 | F6: 46916.51 | G6: 26742.41 | H6: 767.25 | I6: 3210 | J6: 13680.78 | K6: 306.9 | L6: 44707.34 | M6: 2209.17 | N6: 0.0471 | O6: 4.2 | P6: EXIT
A7: 5 | B7: 99a4788cb24856965c36a24e339b6058 | C7: bed_bath_table | D7: 487 | E7: 466 | F7: 42938.66 | G7: 19322.4 | H7: 1095.75 | I7: 3029 | J7: 8024.94 | K7: 175.32 | L7: 31647.41 | M7: 11291.25 | N7: 0.263 | O7: 3.9 | P7: OPTIMIZE
A8: 6 | B8: 3dd2a17168ec895c781a9191c1e95ad7 | C8: computers_accessories | D8: 274 | E8: 255 | F8: 41082.6 | G8: 23417.08 | H8: 616.5 | I8: 2550 | J8: 7129.62 | K8: 246.6 | L8: 33959.8 | M8: 7122.8 | N8: 0.1734 | O8: 4.21 | P8: OPTIMIZE
A9: 7 | B9: 25c38557cf793876c5abdd5931f922db | C9: baby | D9: 38 | E9: 38 | F9: 38907.32 | G9: 16341.07 | H9: 38 | I9: 152 | J9: 1404.63 | K9: 13.68 | L9: 17949.38 | M9: 20957.94 | N9: 0.5387 | O9: 2.68 | P9: EXIT
A10: 8 | B10: 5f504b3a1c75b73d6151be81eb05bdc9 | C10: cool_stuff | D10: 63 | E10: 63 | F10: 37733.9 | G10: 16980.26 | H10: 63 | I10: 252 | J10: 3991.91 | K10: 22.68 | L10: 21309.85 | M10: 16424.05 | N10: 0.4353 | O10: 4.56 | P10: SCALE
A11: 9 | B11: 53b36df67ebb7c41585e8d54d6772e08 | C11: watches_gifts | D11: 323 | E11: 306 | F11: 37683.42 | G11: 15827.04 | H11: 323 | I11: 1224 | J11: 2274.51 | K11: 116.28 | L11: 19764.83 | M11: 17918.59 | N11: 0.4755 | O11: 4.19 | P11: SCALE
A12: 10 | B12: aca2eb7d00ea1a7b8ebd4e68314663af | C12: furniture_decor | D12: 527 | E12: 431 | F12: 37608.9 | G12: 16924.01 | H12: 2635 | I12: 4310 | J12: 7211.86 | K12: 189.72 | L12: 31270.59 | M12: 6338.31 | N12: 0.1685 | O12: 4.02 | P12: OPTIMIZE
A13: 11 | B13: e0d64dcfaa3b6db5c54ca298ae101d05 | C13: watches_gifts | D13: 194 | E13: 194 | F13: 31786.82 | G13: 13350.46 | H13: 194 | I13: 776 | J13: 3557.27 | K13: 69.84 | L13: 17947.57 | M13: 13839.25 | N13: 0.4354 | O13: 3.78 | P13: OPTIMIZE
A14: 12 | B14: d285360f29ac7fd97640bf0baef03de0 | C14: watches_gifts | D14: 123 | E14: 122 | F14: 31623.81 | G14: 13282 | H14: 123 | I14: 488 | J14: 1983.76 | K14: 44.28 | L14: 15921.04 | M14: 15702.77 | N14: 0.4965 | O14: 3.72 | P14: OPTIMIZE
... A402: 400 | B402: 6902c1962dd19d540807d0ab8fade5c6 | C402: watches_gifts | D402: 1 | E402: 1 | F402: 3999.9 | G402: 1679.96 | H402: 1 | I402: 4 | J402: 17.01 | K402: 0.36 | L402: 1702.33 | M402: 2297.57 | N402: 0.5744 | O402: 5 | P402: SCALE

Sheet Profitability_Model
A2: product_id | B2: category | C2: gross_revenue | D2: return_loss | E2: net_revenue_after_returns | F2: cogs | G2: operating_costs | H2: net_profit | I2: gross_margin_pct | J2: net_margin_pct | K2: break_even_price | L2: decision
A3: =tbl_raw[[#This Row],[product_id]] -> bb50f2e236e5eea0100680137654686c | B3: =tbl_raw[[#This Row],[category]] -> health_beauty | C3: =tbl_raw[[#This Row],[gross_revenue]] -> 63885 | D3: =tbl_raw[[#This Row],[return_loss]] -> 70.2 | E3: =C3-D3 -> 63814.8 | F3: =tbl_raw[[#This Row],[cogs]] -> 26831.7 | G3: =SUM(tbl_raw[[#This Row],[storage_cost]:[freight_cost]]) -> 4664.1 | H3: =tbl_profitability[[#This Row],[net_revenue_after_returns]]-tbl_profitability[[#This Row],[cogs]]-tbl_profitability[[#This Row],[operating_costs]] -> 32319 | I3: =(tbl_profitability[[#This Row],[gross_revenue]]-tbl_profitability[[#This Row],[cogs]])/tbl_profitability[[#This Row],[gross_revenue]] -> 0.58 | J3: =tbl_profitability[[#This Row],[net_profit]]/tbl_profitability[[#This Row],[gross_revenue]] -> 0.5058934 | K3: =(tbl_profitability[[#This Row],[cogs]]+tbl_profitability[[#This Row],[return_loss]]+tbl_profitability[[#This Row],[operating_costs]])/tbl_raw[[#This Row],[units_sold]] -> 161.87692 | L3: =tbl_raw[[#This Row],[decision]] -> SCALE
A4: =tbl_raw[[#This Row],[product_id]] -> 6cdd53843498f92890544667809f1595 | B4: =tbl_raw[[#This Row],[category]] -> health_beauty | C4: =tbl_raw[[#This Row],[gross_revenue]] -> 54730.2 | D4: =tbl_raw[[#This Row],[return_loss]] -> 56.16 | E4: =C4-D4 -> 54674.04 | F4: =tbl_raw[[#This Row],[cogs]] -> 22986.68 | G4: =SUM(tbl_raw[[#This Row],[storage_cost]:[freight_cost]]) -> 5123.79 | H4: =tbl_profitability[[#This Row],[net_revenue_after_returns]]-tbl_profitability[[#This Row],[cogs]]-tbl_profitability[[#This Row],[operating_costs]] -> 26563.57 | I4: =(tbl_profitability[[#This Row],[gross_revenue]]-tbl_profitability[[#This Row],[cogs]])/tbl_profitability[[#This Row],[gross_revenue]] -> 0.58000007 | J4: =tbl_profitability[[#This Row],[net_profit]]/tbl_profitability[[#This Row],[gross_revenue]] -> 0.48535489 | K4: =(tbl_profitability[[#This Row],[cogs]]+tbl_profitability[[#This Row],[return_loss]]+tbl_profitability[[#This Row],[operating_costs]])/tbl_raw[[#This Row],[units_sold]] -> 180.55532 | L4: =tbl_raw[[#This Row],[decision]] -> SCALE
A5: =tbl_raw[[#This Row],[product_id]] -> d6160fb7873f184099d9bc95e30376af | B5: =tbl_raw[[#This Row],[category]] -> computers | C5: =tbl_raw[[#This Row],[gross_revenue]] -> 48899.34 | D5: =tbl_raw[[#This Row],[return_loss]] -> 31.5 | E5: =C5-D5 -> 48867.84 | F5: =tbl_raw[[#This Row],[cogs]] -> 27872.62 | G5: =SUM(tbl_raw[[#This Row],[storage_cost]:[freight_cost]]) -> 1855.59 | H5: =tbl_profitability[[#This Row],[net_revenue_after_returns]]-tbl_profitability[[#This Row],[cogs]]-tbl_profitability[[#This Row],[operating_costs]] -> 19139.63 | I5: =(tbl_profitability[[#This Row],[gross_revenue]]-tbl_profitability[[#This Row],[cogs]])/tbl_profitability[[#This Row],[gross_revenue]] -> 0.43000008 | J5: =tbl_profitability[[#This Row],[net_profit]]/tbl_profitability[[#This Row],[gross_revenue]] -> 0.39140876 | K5: =(tbl_profitability[[#This Row],[cogs]]+tbl_profitability[[#This Row],[return_loss]]+tbl_profitability[[#This Row],[operating_costs]])/tbl_raw[[#This Row],[units_sold]] -> 850.27743 | L5: =tbl_raw[[#This Row],[decision]] -> SCALE
A6: =tbl_raw[[#This Row],[product_id]] -> d1c427060a0f73f6b889a5c7c61f2ac4 | B6: =tbl_raw[[#This Row],[category]] -> computers_accessories | C6: =tbl_raw[[#This Row],[gross_revenue]] -> 46916.51 | D6: =tbl_raw[[#This Row],[return_loss]] -> 306.9 | E6: =C6-D6 -> 46609.61 | F6: =tbl_raw[[#This Row],[cogs]] -> 26742.41 | G6: =SUM(tbl_raw[[#This Row],[storage_cost]:[freight_cost]]) -> 17658.03 | H6: =tbl_profitability[[#This Row],[net_revenue_after_returns]]-tbl_profitability[[#This Row],[cogs]]-tbl_profitability[[#This Row],[operating_costs]] -> 2209.17 | I6: =(tbl_profitability[[#This Row],[gross_revenue]]-tbl_profitability[[#This Row],[cogs]])/tbl_profitability[[#This Row],[gross_revenue]] -> 0.43000001 | J6: =tbl_profitability[[#This Row],[net_profit]]/tbl_profitability[[#This Row],[gross_revenue]] -> 0.047087262 | K6: =(tbl_profitability[[#This Row],[cogs]]+tbl_profitability[[#This Row],[return_loss]]+tbl_profitability[[#This Row],[operating_costs]])/tbl_raw[[#This Row],[units_sold]] -> 131.10657 | L6: =tbl_raw[[#This Row],[decision]] -> EXIT
A7: =tbl_raw[[#This Row],[product_id]] -> 99a4788cb24856965c36a24e339b6058 | B7: =tbl_raw[[#This Row],[category]] -> bed_bath_table | C7: =tbl_raw[[#This Row],[gross_revenue]] -> 42938.66 | D7: =tbl_raw[[#This Row],[return_loss]] -> 175.32 | E7: =C7-D7 -> 42763.34 | F7: =tbl_raw[[#This Row],[cogs]] -> 19322.4 | G7: =SUM(tbl_raw[[#This Row],[storage_cost]:[freight_cost]]) -> 12149.69 | H7: =tbl_profitability[[#This Row],[net_revenue_after_returns]]-tbl_profitability[[#This Row],[cogs]]-tbl_profitability[[#This Row],[operating_costs]] -> 11291.25 | I7: =(tbl_profitability[[#This Row],[gross_revenue]]-tbl_profitability[[#This Row],[cogs]])/tbl_profitability[[#This Row],[gross_revenue]] -> 0.54999993 | J7: =tbl_profitability[[#This Row],[net_profit]]/tbl_profitability[[#This Row],[gross_revenue]] -> 0.26296233 | K7: =(tbl_profitability[[#This Row],[cogs]]+tbl_profitability[[#This Row],[return_loss]]+tbl_profitability[[#This Row],[operating_costs]])/tbl_raw[[#This Row],[units_sold]] -> 64.984415 | L7: =tbl_raw[[#This Row],[decision]] -> OPTIMIZE
A8: =tbl_raw[[#This Row],[product_id]] -> 3dd2a17168ec895c781a9191c1e95ad7 | B8: =tbl_raw[[#This Row],[category]] -> computers_accessories | C8: =tbl_raw[[#This Row],[gross_revenue]] -> 41082.6 | D8: =tbl_raw[[#This Row],[return_loss]] -> 246.6 | E8: =C8-D8 -> 40836 | F8: =tbl_raw[[#This Row],[cogs]] -> 23417.08 | G8: =SUM(tbl_raw[[#This Row],[storage_cost]:[freight_cost]]) -> 10296.12 | H8: =tbl_profitability[[#This Row],[net_revenue_after_returns]]-tbl_profitability[[#This Row],[cogs]]-tbl_profitability[[#This Row],[operating_costs]] -> 7122.8 | I8: =(tbl_profitability[[#This Row],[gross_revenue]]-tbl_profitability[[#This Row],[cogs]])/tbl_profitability[[#This Row],[gross_revenue]] -> 0.43000005 | J8: =tbl_profitability[[#This Row],[net_profit]]/tbl_profitability[[#This Row],[gross_revenue]] -> 0.17337754 | K8: =(tbl_profitability[[#This Row],[cogs]]+tbl_profitability[[#This Row],[return_loss]]+tbl_profitability[[#This Row],[operating_costs]])/tbl_raw[[#This Row],[units_sold]] -> 123.94088 | L8: =tbl_raw[[#This Row],[decision]] -> OPTIMIZE
A9: =tbl_raw[[#This Row],[product_id]] -> 25c38557cf793876c5abdd5931f922db | B9: =tbl_raw[[#This Row],[category]] -> baby | C9: =tbl_raw[[#This Row],[gross_revenue]] -> 38907.32 | D9: =tbl_raw[[#This Row],[return_loss]] -> 13.68 | E9: =C9-D9 -> 38893.64 | F9: =tbl_raw[[#This Row],[cogs]] -> 16341.07 | G9: =SUM(tbl_raw[[#This Row],[storage_cost]:[freight_cost]]) -> 1594.63 | H9: =tbl_profitability[[#This Row],[net_revenue_after_returns]]-tbl_profitability[[#This Row],[cogs]]-tbl_profitability[[#This Row],[operating_costs]] -> 20957.94 | I9: =(tbl_profitability[[#This Row],[gross_revenue]]-tbl_profitability[[#This Row],[cogs]])/tbl_profitability[[#This Row],[gross_revenue]] -> 0.58000011 | J9: =tbl_profitability[[#This Row],[net_profit]]/tbl_profitability[[#This Row],[gross_revenue]] -> 0.53866316 | K9: =(tbl_profitability[[#This Row],[cogs]]+tbl_profitability[[#This Row],[return_loss]]+tbl_profitability[[#This Row],[operating_costs]])/tbl_raw[[#This Row],[units_sold]] -> 472.35211 | L9: =tbl_raw[[#This Row],[decision]] -> EXIT
A10: =tbl_raw[[#This Row],[product_id]] -> 5f504b3a1c75b73d6151be81eb05bdc9 | B10: =tbl_raw[[#This Row],[category]] -> cool_stuff | C10: =tbl_raw[[#This Row],[gross_revenue]] -> 37733.9 | D10: =tbl_raw[[#This Row],[return_loss]] -> 22.68 | E10: =C10-D10 -> 37711.22 | F10: =tbl_raw[[#This Row],[cogs]] -> 16980.26 | G10: =SUM(tbl_raw[[#This Row],[storage_cost]:[freight_cost]]) -> 4306.91 | H10: =tbl_profitability[[#This Row],[net_revenue_after_returns]]-tbl_profitability[[#This Row],[cogs]]-tbl_profitability[[#This Row],[operating_costs]] -> 16424.05 | I10: =(tbl_profitability[[#This Row],[gross_revenue]]-tbl_profitability[[#This Row],[cogs]])/tbl_profitability[[#This Row],[gross_revenue]] -> 0.54999987 | J10: =tbl_profitability[[#This Row],[net_profit]]/tbl_profitability[[#This Row],[gross_revenue]] -> 0.43525981 | K10: =(tbl_profitability[[#This Row],[cogs]]+tbl_profitability[[#This Row],[return_loss]]+tbl_profitability[[#This Row],[operating_costs]])/tbl_raw[[#This Row],[units_sold]] -> 338.25159 | L10: =tbl_raw[[#This Row],[decision]] -> SCALE
A11: =tbl_raw[[#This Row],[product_id]] -> 53b36df67ebb7c41585e8d54d6772e08 | B11: =tbl_raw[[#This Row],[category]] -> watches_gifts | C11: =tbl_raw[[#This Row],[gross_revenue]] -> 37683.42 | D11: =tbl_raw[[#This Row],[return_loss]] -> 116.28 | E11: =C11-D11 -> 37567.14 | F11: =tbl_raw[[#This Row],[cogs]] -> 15827.04 | G11: =SUM(tbl_raw[[#This Row],[storage_cost]:[freight_cost]]) -> 3821.51 | H11: =tbl_profitability[[#This Row],[net_revenue_after_returns]]-tbl_profitability[[#This Row],[cogs]]-tbl_profitability[[#This Row],[operating_costs]] -> 17918.59 | I11: =(tbl_profitability[[#This Row],[gross_revenue]]-tbl_profitability[[#This Row],[cogs]])/tbl_profitability[[#This Row],[gross_revenue]] -> 0.5799999 | J11: =tbl_profitability[[#This Row],[net_profit]]/tbl_profitability[[#This Row],[gross_revenue]] -> 0.47550328 | K11: =(tbl_profitability[[#This Row],[cogs]]+tbl_profitability[[#This Row],[return_loss]]+tbl_profitability[[#This Row],[operating_costs]])/tbl_raw[[#This Row],[units_sold]] -> 61.191424 | L11: =tbl_raw[[#This Row],[decision]] -> SCALE
A12: =tbl_raw[[#This Row],[product_id]] -> aca2eb7d00ea1a7b8ebd4e68314663af | B12: =tbl_raw[[#This Row],[category]] -> furniture_decor | C12: =tbl_raw[[#This Row],[gross_revenue]] -> 37608.9 | D12: =tbl_raw[[#This Row],[return_loss]] -> 189.72 | E12: =C12-D12 -> 37419.18 | F12: =tbl_raw[[#This Row],[cogs]] -> 16924.01 | G12: =SUM(tbl_raw[[#This Row],[storage_cost]:[freight_cost]]) -> 14156.86 | H12: =tbl_profitability[[#This Row],[net_revenue_after_returns]]-tbl_profitability[[#This Row],[cogs]]-tbl_profitability[[#This Row],[operating_costs]] -> 6338.31 | I12: =(tbl_profitability[[#This Row],[gross_revenue]]-tbl_profitability[[#This Row],[cogs]])/tbl_profitability[[#This Row],[gross_revenue]] -> 0.54999987 | J12: =tbl_profitability[[#This Row],[net_profit]]/tbl_profitability[[#This Row],[gross_revenue]] -> 0.16853218 | K12: =(tbl_profitability[[#This Row],[cogs]]+tbl_profitability[[#This Row],[return_loss]]+tbl_profitability[[#This Row],[operating_costs]])/tbl_raw[[#This Row],[units_sold]] -> 59.336983 | L12: =tbl_raw[[#This Row],[decision]] -> OPTIMIZE
A13: =tbl_raw[[#This Row],[product_id]] -> e0d64dcfaa3b6db5c54ca298ae101d05 | B13: =tbl_raw[[#This Row],[category]] -> watches_gifts | C13: =tbl_raw[[#This Row],[gross_revenue]] -> 31786.82 | D13: =tbl_raw[[#This Row],[return_loss]] -> 69.84 | E13: =C13-D13 -> 31716.98 | F13: =tbl_raw[[#This Row],[cogs]] -> 13350.46 | G13: =SUM(tbl_raw[[#This Row],[storage_cost]:[freight_cost]]) -> 4527.27 | H13: =tbl_profitability[[#This Row],[net_revenue_after_returns]]-tbl_profitability[[#This Row],[cogs]]-tbl_profitability[[#This Row],[operating_costs]] -> 13839.25 | I13: =(tbl_profitability[[#This Row],[gross_revenue]]-tbl_profitability[[#This Row],[cogs]])/tbl_profitability[[#This Row],[gross_revenue]] -> 0.58000014 | J13: =tbl_profitability[[#This Row],[net_profit]]/tbl_profitability[[#This Row],[gross_revenue]] -> 0.43537699 | K13: =(tbl_profitability[[#This Row],[cogs]]+tbl_profitability[[#This Row],[return_loss]]+tbl_profitability[[#This Row],[operating_costs]])/tbl_raw[[#This Row],[units_sold]] -> 92.513247 | L13: =tbl_raw[[#This Row],[decision]] -> OPTIMIZE
A14: =tbl_raw[[#This Row],[product_id]] -> d285360f29ac7fd97640bf0baef03de0 | B14: =tbl_raw[[#This Row],[category]] -> watches_gifts | C14: =tbl_raw[[#This Row],[gross_revenue]] -> 31623.81 | D14: =tbl_raw[[#This Row],[return_loss]] -> 44.28 | E14: =C14-D14 -> 31579.53 | F14: =tbl_raw[[#This Row],[cogs]] -> 13282 | G14: =SUM(tbl_raw[[#This Row],[storage_cost]:[freight_cost]]) -> 2594.76 | H14: =tbl_profitability[[#This Row],[net_revenue_after_returns]]-tbl_profitability[[#This Row],[cogs]]-tbl_profitability[[#This Row],[operating_costs]] -> 15702.77 | I14: =(tbl_profitability[[#This Row],[gross_revenue]]-tbl_profitability[[#This Row],[cogs]])/tbl_profitability[[#This Row],[gross_revenue]] -> 0.58000001 | J14: =tbl_profitability[[#This Row],[net_profit]]/tbl_profitability[[#This Row],[gross_revenue]] -> 0.49654896 | K14: =(tbl_profitability[[#This Row],[cogs]]+tbl_profitability[[#This Row],[return_loss]]+tbl_profitability[[#This Row],[operating_costs]])/tbl_raw[[#This Row],[units_sold]] -> 129.43935 | L14: =tbl_raw[[#This Row],[decision]] -> OPTIMIZE
... A402: =tbl_raw[[#This Row],[product_id]] -> 6902c1962dd19d540807d0ab8fade5c6 | B402: =tbl_raw[[#This Row],[category]] -> watches_gifts | C402: =tbl_raw[[#This Row],[gross_revenue]] -> 3999.9 | D402: =tbl_raw[[#This Row],[return_loss]] -> 0.36 | E402: =C402-D402 -> 3999.54 | F402: =tbl_raw[[#This Row],[cogs]] -> 1679.96 | G402: =SUM(tbl_raw[[#This Row],[storage_cost]:[freight_cost]]) -> 22.01 | H402: =tbl_profitability[[#This Row],[net_revenue_after_returns]]-tbl_profitability[[#This Row],[cogs]]-tbl_profitability[[#This Row],[operating_costs]] -> 2297.57 | I402: =(tbl_profitability[[#This Row],[gross_revenue]]-tbl_profitability[[#This Row],[cogs]])/tbl_profitability[[#This Row],[gross_revenue]] -> 0.5799995 | J402: =tbl_profitability[[#This Row],[net_profit]]/tbl_profitability[[#This Row],[gross_revenue]] -> 0.57440686 | K402: =(tbl_profitability[[#This Row],[cogs]]+tbl_profitability[[#This Row],[return_loss]]+tbl_profitability[[#This Row],[operating_costs]])/tbl_raw[[#This Row],[units_sold]] -> 1702.33 | L402: =tbl_raw[[#This Row],[decision]] -> SCALE
A405: MODEL RECONCILIATION - Excel vs SQL Source of Truth
A407: Check | B407: Tolerance | C407: Result | D407: Status
A408: Max |Δ| Net Profit (BRL) | B408: < R$ 0.01 | C408: {=MAX(ABS(tbl_profitability[net_profit]-tbl_raw[net_profit_sql_check]))} -> 7.2759576e-12 | D408: =IF(C408<0.01,"✓ Pass","✗ Fail") -> ✓ Pass
A409: Max |Δ| Net Margin (pp) | B409: < 0.01% | C409: {=MAX(ABS(tbl_profitability[net_margin_pct]-tbl_raw[net_margin_pct_sql_check]))} -> 5e-05 | D409: =IF(C409<0.0001,"✓ Pass","✗ Fail") -> ✓ Pass
A410: Row count Excel vs SQL | B410: =400 -> 400 | C410: =ROWS(tbl_profitability[]) -> 400 | D410: =IF(C410=400,"✓ Pass","✗ Fail") -> ✓ Pass
A412: =IF(COUNTIF(D408:D410,"✓ Pass")=3,"✓ RECONCILED - Model ties to SQL source within tolerance.","✗ INVESTIGATE — One or more checks failed. Do not rely on downstream tabs until resolved.") -> ✓ RECONCILED - Model ties to SQL source within tolerance.

Sheet Scenario_Analysis
C1: Baseline | F1: Scenario A — COGS +% | J1: Scenario B — Returns +pp | N1: Scenario C — Price −% | R1: Stability | T1: Scenario | U1: Description
A2: product_id | B2: category | C2: net_profit | D2: net_margin_pct | E2: decision | F2: net_profit_A | G2: net_margin_A | H2: margin_delta_A | I2: decision_A | J2: net_profit_B | K2: net_margin_B | L2: margin_delta_B | M2: decision_B | N2: net_profit_C | O2: net_margin_C | P2: margin_delta_C | Q2: decision_C | R2: stability_flag | T2: Scenario A | U2: COGS increase — multiplier applied to cost of goods sold | Y2: 0.1
A3: =tbl_raw[[#This Row],[product_id]] -> bb50f2e236e5eea0100680137654686c | B3: =tbl_raw[[#This Row],[category]] -> health_beauty | C3: =tbl_profitability[[#This Row],[net_profit]] -> 32319 | D3: =tbl_profitability[[#This Row],[net_margin_pct]] -> 0.5058934 | E3: =tbl_profitability[[#This Row],[decision]] -> SCALE | F3: =tbl_raw[[#This Row],[gross_revenue]]-tbl_raw[[#This Row],[return_loss]]-tbl_raw[[#This Row],[cogs]]*(1+scn_A_cogs_up)-(tbl_raw[[#This Row],[storage_cost]]+tbl_raw[[#This Row],[fulfillment_cost]]+tbl_raw[[#This Row],[freight_cost]]) -> 29635.83 | G3: =tbl_scenarios[[#This Row],[net_profit_A]]/tbl_raw[[#This Row],[gross_revenue]] -> 0.4638934 | H3: =tbl_scenarios[[#This Row],[net_margin_A]]-tbl_scenarios[[#This Row],[net_margin_pct]] -> -0.042 | I3: =IF(OR(tbl_scenarios[[#This Row],[net_margin_A]]<0.1,tbl_raw[[#This Row],[avg_review_score]]<3),"EXIT",IF(AND(tbl_scenarios[[#This Row],[net_margin_A]]>=0.25,tbl_raw[[#This Row],[avg_review_score]]>=4),"SCALE","OPTIMIZE")) -> SCALE | J3: =tbl_raw[[#This Row],[gross_revenue]]-tbl_raw[[#This Row],[return_loss]]*(1+scn_B_returns_up/0.05)-tbl_raw[[#This Row],[cogs]]-(tbl_raw[[#This Row],[storage_cost]]+tbl_raw[[#This Row],[fulfillment_cost]]+tbl_raw[[#This Row],[freight_cost]]) -> 32248.8 | K3: =tbl_scenarios[[#This Row],[net_profit_B]]/tbl_raw[[#This Row],[gross_revenue]] -> 0.50479455 | L3: =tbl_scenarios[[#This Row],[net_margin_B]]-tbl_scenarios[[#This Row],[net_margin_pct]] -> -0.0010988495 | M3: =IF(OR(tbl_scenarios[[#This Row],[net_margin_B]]<0.1,tbl_raw[[#This Row],[avg_review_score]]<3),"EXIT",IF(AND(tbl_scenarios[[#This Row],[net_margin_B]]>=0.25,tbl_raw[[#This Row],[avg_review_score]]>=4),"SCALE","OPTIMIZE")) -> SCALE | N3: =tbl_raw[[#This Row],[gross_revenue]]*(1-scn_C_price_down)-tbl_raw[[#This Row],[return_loss]]-tbl_raw[[#This Row],[cogs]]-(tbl_raw[[#This Row],[storage_cost]]+tbl_raw[[#This Row],[fulfillment_cost]]+tbl_raw[[#This Row],[freight_cost]]) -> 29124.75 | O3: =tbl_scenarios[[#This Row],[net_profit_C]]/(tbl_raw[[#This Row],[gross_revenue]]*(1-scn_C_price_down)) -> 0.47988779 | P3: =tbl_scenarios[[#This Row],[net_margin_C]]-tbl_scenarios[[#This Row],[net_margin_pct]] -> -0.02600561 | Q3: =IF(OR(tbl_scenarios[[#This Row],[net_margin_C]]<0.1,tbl_raw[[#This Row],[avg_review_score]]<3),"EXIT",IF(AND(tbl_scenarios[[#This Row],[net_margin_C]]>=0.25,tbl_raw[[#This Row],[avg_review_score]]>=4),"SCALE","OPTIMIZE")) -> SCALE | R3: =IF(OR(tbl_scenarios[[#This Row],[decision_A]]<>tbl_scenarios[[#This Row],[decision]],tbl_scenarios[[#This Row],[decision_B]]<>tbl_scenarios[[#This Row],[decision]],tbl_scenarios[[#This Row],[decision_C]]<>tbl_scenarios[[#This Row],[decision]]),"Decision changes","Stable") -> Stable | T3: Scenario B | U3: Return-rate increase in percentage points (rate-derived: return_loss × (1 + Δ / 5%)) | Y3: 0.05
A4: =tbl_raw[[#This Row],[product_id]] -> 6cdd53843498f92890544667809f1595 | B4: =tbl_raw[[#This Row],[category]] -> health_beauty | C4: =tbl_profitability[[#This Row],[net_profit]] -> 26563.57 | D4: =tbl_profitability[[#This Row],[net_margin_pct]] -> 0.48535489 | E4: =tbl_profitability[[#This Row],[decision]] -> SCALE | F4: =tbl_raw[[#This Row],[gross_revenue]]-tbl_raw[[#This Row],[return_loss]]-tbl_raw[[#This Row],[cogs]]*(1+scn_A_cogs_up)-(tbl_raw[[#This Row],[storage_cost]]+tbl_raw[[#This Row],[fulfillment_cost]]+tbl_raw[[#This Row],[freight_cost]]) -> 24264.902 | G4: =tbl_scenarios[[#This Row],[net_profit_A]]/tbl_raw[[#This Row],[gross_revenue]] -> 0.44335489 | H4: =tbl_scenarios[[#This Row],[net_margin_A]]-tbl_scenarios[[#This Row],[net_margin_pct]] -> -0.041999993 | I4: =IF(OR(tbl_scenarios[[#This Row],[net_margin_A]]<0.1,tbl_raw[[#This Row],[avg_review_score]]<3),"EXIT",IF(AND(tbl_scenarios[[#This Row],[net_margin_A]]>=0.25,tbl_raw[[#This Row],[avg_review_score]]>=4),"SCALE","OPTIMIZE")) -> SCALE | J4: =tbl_raw[[#This Row],[gross_revenue]]-tbl_raw[[#This Row],[return_loss]]*(1+scn_B_returns_up/0.05)-tbl_raw[[#This Row],[cogs]]-(tbl_raw[[#This Row],[storage_cost]]+tbl_raw[[#This Row],[fulfillment_cost]]+tbl_raw[[#This Row],[freight_cost]]) -> 26507.41 | K4: =tbl_scenarios[[#This Row],[net_profit_B]]/tbl_raw[[#This Row],[gross_revenue]] -> 0.48432876 | L4: =tbl_scenarios[[#This Row],[net_margin_B]]-tbl_scenarios[[#This Row],[net_margin_pct]] -> -0.0010261245 | M4: =IF(OR(tbl_scenarios[[#This Row],[net_margin_B]]<0.1,tbl_raw[[#This Row],[avg_review_score]]<3),"EXIT",IF(AND(tbl_scenarios[[#This Row],[net_margin_B]]>=0.25,tbl_raw[[#This Row],[avg_review_score]]>=4),"SCALE","OPTIMIZE")) -> SCALE | N4: =tbl_raw[[#This Row],[gross_revenue]]*(1-scn_C_price_down)-tbl_raw[[#This Row],[return_loss]]-tbl_raw[[#This Row],[cogs]]-(tbl_raw[[#This Row],[storage_cost]]+tbl_raw[[#This Row],[fulfillment_cost]]+tbl_raw[[#This Row],[freight_cost]]) -> 23827.06 | O4: =tbl_scenarios[[#This Row],[net_profit_C]]/(tbl_raw[[#This Row],[gross_revenue]]*(1-scn_C_price_down)) -> 0.4582683 | P4: =tbl_scenarios[[#This Row],[net_margin_C]]-tbl_scenarios[[#This Row],[net_margin_pct]] -> -0.027086585 | Q4: =IF(OR(tbl_scenarios[[#This Row],[net_margin_C]]<0.1,tbl_raw[[#This Row],[avg_review_score]]<3),"EXIT",IF(AND(tbl_scenarios[[#This Row],[net_margin_C]]>=0.25,tbl_raw[[#This Row],[avg_review_score]]>=4),"SCALE","OPTIMIZE")) -> SCALE | R4: =IF(OR(tbl_scenarios[[#This Row],[decision_A]]<>tbl_scenarios[[#This Row],[decision]],tbl_scenarios[[#This Row],[decision_B]]<>tbl_scenarios[[#This Row],[decision]],tbl_scenarios[[#This Row],[decision_C]]<>tbl_scenarios[[#This Row],[decision]]),"Decision changes","Stable") -> Stable | T4: Scenario C | U4: Sale price reduction — multiplier on gross revenue | Y4: 0.05
A5: =tbl_raw[[#This Row],[product_id]] -> d6160fb7873f184099d9bc95e30376af | B5: =tbl_raw[[#This Row],[category]] -> computers | C5: =tbl_profitability[[#This Row],[net_profit]] -> 19139.63 | D5: =tbl_profitability[[#This Row],[net_margin_pct]] -> 0.39140876 | E5: =tbl_profitability[[#This Row],[decision]] -> SCALE | F5: =tbl_raw[[#This Row],[gross_revenue]]-tbl_raw[[#This Row],[return_loss]]-tbl_raw[[#This Row],[cogs]]*(1+scn_A_cogs_up)-(tbl_raw[[#This Row],[storage_cost]]+tbl_raw[[#This Row],[fulfillment_cost]]+tbl_raw[[#This Row],[freight_cost]]) -> 16352.368 | G5: =tbl_scenarios[[#This Row],[net_profit_A]]/tbl_raw[[#This Row],[gross_revenue]] -> 0.33440877 | H5: =tbl_scenarios[[#This Row],[net_margin_A]]-tbl_scenarios[[#This Row],[net_margin_pct]] -> -0.056999992 | I5: =IF(OR(tbl_scenarios[[#This Row],[net_margin_A]]<0.1,tbl_raw[[#This Row],[avg_review_score]]<3),"EXIT",IF(AND(tbl_scenarios[[#This Row],[net_margin_A]]>=0.25,tbl_raw[[#This Row],[avg_review_score]]>=4),"SCALE","OPTIMIZE")) -> SCALE | J5: =tbl_raw[[#This Row],[gross_revenue]]-tbl_raw[[#This Row],[return_loss]]*(1+scn_B_returns_up/0.05)-tbl_raw[[#This Row],[cogs]]-(tbl_raw[[#This Row],[storage_cost]]+tbl_raw[[#This Row],[fulfillment_cost]]+tbl_raw[[#This Row],[freight_cost]]) -> 19108.13 | K5: =tbl_scenarios[[#This Row],[net_profit_B]]/tbl_raw[[#This Row],[gross_revenue]] -> 0.39076458 | L5: =tbl_scenarios[[#This Row],[net_margin_B]]-tbl_scenarios[[#This Row],[net_margin_pct]] -> -0.00064418047 | M5: =IF(OR(tbl_scenarios[[#This Row],[net_margin_B]]<0.1,tbl_raw[[#This Row],[avg_review_score]]<3),"EXIT",IF(AND(tbl_scenarios[[#This Row],[net_margin_B]]>=0.25,tbl_raw[[#This Row],[avg_review_score]]>=4),"SCALE","OPTIMIZE")) -> SCALE | N5: =tbl_raw[[#This Row],[gross_revenue]]*(1-scn_C_price_down)-tbl_raw[[#This Row],[return_loss]]-tbl_raw[[#This Row],[cogs]]-(tbl_raw[[#This Row],[storage_cost]]+tbl_raw[[#This Row],[fulfillment_cost]]+tbl_raw[[#This Row],[freight_cost]]) -> 16694.663 | O5: =tbl_scenarios[[#This Row],[net_profit_C]]/(tbl_raw[[#This Row],[gross_revenue]]*(1-scn_C_price_down)) -> 0.35937764 | P5: =tbl_scenarios[[#This Row],[net_margin_C]]-tbl_scenarios[[#This Row],[net_margin_pct]] -> -0.032031118 | Q5: =IF(OR(tbl_scenarios[[#This Row],[net_margin_C]]<0.1,tbl_raw[[#This Row],[avg_review_score]]<3),"EXIT",IF(AND(tbl_scenarios[[#This Row],[net_margin_C]]>=0.25,tbl_raw[[#This Row],[avg_review_score]]>=4),"SCALE","OPTIMIZE")) -> SCALE | R5: =IF(OR(tbl_scenarios[[#This Row],[decision_A]]<>tbl_scenarios[[#This Row],[decision]],tbl_scenarios[[#This Row],[decision_B]]<>tbl_scenarios[[#This Row],[decision]],tbl_scenarios[[#This Row],[decision_C]]<>tbl_scenarios[[#This Row],[decision]]),"Decision changes","Stable") -> Stable
A6: =tbl_raw[[#This Row],[product_id]] -> d1c427060a0f73f6b889a5c7c61f2ac4 | B6: =tbl_raw[[#This Row],[category]] -> computers_accessories | C6: =tbl_profitability[[#This Row],[net_profit]] -> 2209.17 | D6: =tbl_profitability[[#This Row],[net_margin_pct]] -> 0.047087262 | E6: =tbl_profitability[[#This Row],[decision]] -> EXIT | F6: =tbl_raw[[#This Row],[gross_revenue]]-tbl_raw[[#This Row],[return_loss]]-tbl_raw[[#This Row],[cogs]]*(1+scn_A_cogs_up)-(tbl_raw[[#This Row],[storage_cost]]+tbl_raw[[#This Row],[fulfillment_cost]]+tbl_raw[[#This Row],[freight_cost]]) -> -465.071 | G6: =tbl_scenarios[[#This Row],[net_profit_A]]/tbl_raw[[#This Row],[gross_revenue]] -> -0.0099127365 | H6: =tbl_scenarios[[#This Row],[net_margin_A]]-tbl_scenarios[[#This Row],[net_margin_pct]] -> -0.056999999 | I6: =IF(OR(tbl_scenarios[[#This Row],[net_margin_A]]<0.1,tbl_raw[[#This Row],[avg_review_score]]<3),"EXIT",IF(AND(tbl_scenarios[[#This Row],[net_margin_A]]>=0.25,tbl_raw[[#This Row],[avg_review_score]]>=4),"SCALE","OPTIMIZE")) -> EXIT | J6: =tbl_raw[[#This Row],[gross_revenue]]-tbl_raw[[#This Row],[return_loss]]*(1+scn_B_returns_up/0.05)-tbl_raw[[#This Row],[cogs]]-(tbl_raw[[#This Row],[storage_cost]]+tbl_raw[[#This Row],[fulfillment_cost]]+tbl_raw[[#This Row],[freight_cost]]) -> 1902.27 | K6: =tbl_scenarios[[#This Row],[net_profit_B]]/tbl_raw[[#This Row],[gross_revenue]] -> 0.040545855 | L6: =tbl_scenarios[[#This Row],[net_margin_B]]-tbl_scenarios[[#This Row],[net_margin_pct]] -> -0.0065414073 | M6: =IF(OR(tbl_scenarios[[#This Row],[net_margin_B]]<0.1,tbl_raw[[#This Row],[avg_review_score]]<3),"EXIT",IF(AND(tbl_scenarios[[#This Row],[net_margin_B]]>=0.25,tbl_raw[[#This Row],[avg_review_score]]>=4),"SCALE","OPTIMIZE")) -> EXIT | N6: =tbl_raw[[#This Row],[gross_revenue]]*(1-scn_C_price_down)-tbl_raw[[#This Row],[return_loss]]-tbl_raw[[#This Row],[cogs]]-(tbl_raw[[#This Row],[storage_cost]]+tbl_raw[[#This Row],[fulfillment_cost]]+tbl_raw[[#This Row],[freight_cost]]) -> -136.6555 | O6: =tbl_scenarios[[#This Row],[net_profit_C]]/(tbl_raw[[#This Row],[gross_revenue]]*(1-scn_C_price_down)) -> -0.00306604 | P6: =tbl_scenarios[[#This Row],[net_margin_C]]-tbl_scenarios[[#This Row],[net_margin_pct]] -> -0.050153302 | Q6: =IF(OR(tbl_scenarios[[#This Row],[net_margin_C]]<0.1,tbl_raw[[#This Row],[avg_review_score]]<3),"EXIT",IF(AND(tbl_scenarios[[#This Row],[net_margin_C]]>=0.25,tbl_raw[[#This Row],[avg_review_score]]>=4),"SCALE","OPTIMIZE")) -> EXIT | R6: =IF(OR(tbl_scenarios[[#This Row],[decision_A]]<>tbl_scenarios[[#This Row],[decision]],tbl_scenarios[[#This Row],[decision_B]]<>tbl_scenarios[[#This Row],[decision]],tbl_scenarios[[#This Row],[decision_C]]<>tbl_scenarios[[#This Row],[decision]]),"Decision changes","Stable") -> Stable | T6: Note: scenarios are independent (not combined). Each scenario applies its shock while holding the other two variables at baseline. Edit the yellow cells above to change assumptions.
A7: =tbl_raw[[#This Row],[product_id]] -> 99a4788cb24856965c36a24e339b6058 | B7: =tbl_raw[[#This Row],[category]] -> bed_bath_table | C7: =tbl_profitability[[#This Row],[net_profit]] -> 11291.25 | D7: =tbl_profitability[[#This Row],[net_margin_pct]] -> 0.26296233 | E7: =tbl_profitability[[#This Row],[decision]] -> OPTIMIZE | F7: =tbl_raw[[#This Row],[gross_revenue]]-tbl_raw[[#This Row],[return_loss]]-tbl_raw[[#This Row],[cogs]]*(1+scn_A_cogs_up)-(tbl_raw[[#This Row],[storage_cost]]+tbl_raw[[#This Row],[fulfillment_cost]]+tbl_raw[[#This Row],[freight_cost]]) -> 9359.01 | G7: =tbl_scenarios[[#This Row],[net_profit_A]]/tbl_raw[[#This Row],[gross_revenue]] -> 0.21796232 | H7: =tbl_scenarios[[#This Row],[net_margin_A]]-tbl_scenarios[[#This Row],[net_margin_pct]] -> -0.045000007 | I7: =IF(OR(tbl_scenarios[[#This Row],[net_margin_A]]<0.1,tbl_raw[[#This Row],[avg_review_score]]<3),"EXIT",IF(AND(tbl_scenarios[[#This Row],[net_margin_A]]>=0.25,tbl_raw[[#This Row],[avg_review_score]]>=4),"SCALE","OPTIMIZE")) -> OPTIMIZE | J7: =tbl_raw[[#This Row],[gross_revenue]]-tbl_raw[[#This Row],[return_loss]]*(1+scn_B_returns_up/0.05)-tbl_raw[[#This Row],[cogs]]-(tbl_raw[[#This Row],[storage_cost]]+tbl_raw[[#This Row],[fulfillment_cost]]+tbl_raw[[#This Row],[freight_cost]]) -> 11115.93 | K7: =tbl_scenarios[[#This Row],[net_profit_B]]/tbl_raw[[#This Row],[gross_revenue]] -> 0.25887929 | L7: =tbl_scenarios[[#This Row],[net_margin_B]]-tbl_scenarios[[#This Row],[net_margin_pct]] -> -0.0040830338 | M7: =IF(OR(tbl_scenarios[[#This Row],[net_margin_B]]<0.1,tbl_raw[[#This Row],[avg_review_score]]<3),"EXIT",IF(AND(tbl_scenarios[[#This Row],[net_margin_B]]>=0.25,tbl_raw[[#This Row],[avg_review_score]]>=4),"SCALE","OPTIMIZE")) -> OPTIMIZE | N7: =tbl_raw[[#This Row],[gross_revenue]]*(1-scn_C_price_down)-tbl_raw[[#This Row],[return_loss]]-tbl_raw[[#This Row],[cogs]]-(tbl_raw[[#This Row],[storage_cost]]+tbl_raw[[#This Row],[fulfillment_cost]]+tbl_raw[[#This Row],[freight_cost]]) -> 9144.317 | O7: =tbl_scenarios[[#This Row],[net_profit_C]]/(tbl_raw[[#This Row],[gross_revenue]]*(1-scn_C_price_down)) -> 0.22417087 | P7: =tbl_scenarios[[#This Row],[net_margin_C]]-tbl_scenarios[[#This Row],[net_margin_pct]] -> -0.038791456 | Q7: =IF(OR(tbl_scenarios[[#This Row],[net_margin_C]]<0.1,tbl_raw[[#This Row],[avg_review_score]]<3),"EXIT",IF(AND(tbl_scenarios[[#This Row],[net_margin_C]]>=0.25,tbl_raw[[#This Row],[avg_review_score]]>=4),"SCALE","OPTIMIZE")) -> OPTIMIZE | R7: =IF(OR(tbl_scenarios[[#This Row],[decision_A]]<>tbl_scenarios[[#This Row],[decision]],tbl_scenarios[[#This Row],[decision_B]]<>tbl_scenarios[[#This Row],[decision]],tbl_scenarios[[#This Row],[decision_C]]<>tbl_scenarios[[#This Row],[decision]]),"Decision changes","Stable") -> Stable
A8: =tbl_raw[[#This Row],[product_id]] -> 3dd2a17168ec895c781a9191c1e95ad7 | B8: =tbl_raw[[#This Row],[category]] -> computers_accessories | C8: =tbl_profitability[[#This Row],[net_profit]] -> 7122.8 | D8: =tbl_profitability[[#This Row],[net_margin_pct]] -> 0.17337754 | E8: =tbl_profitability[[#This Row],[decision]] -> OPTIMIZE | F8: =tbl_raw[[#This Row],[gross_revenue]]-tbl_raw[[#This Row],[return_loss]]-tbl_raw[[#This Row],[cogs]]*(1+scn_A_cogs_up)-(tbl_raw[[#This Row],[storage_cost]]+tbl_raw[[#This Row],[fulfillment_cost]]+tbl_raw[[#This Row],[freight_cost]]) -> 4781.092 | G8: =tbl_scenarios[[#This Row],[net_profit_A]]/tbl_raw[[#This Row],[gross_revenue]] -> 0.11637754 | H8: =tbl_scenarios[[#This Row],[net_margin_A]]-tbl_scenarios[[#This Row],[net_margin_pct]] -> -0.056999995 | I8: =IF(OR(tbl_scenarios[[#This Row],[net_margin_A]]<0.1,tbl_raw[[#This Row],[avg_review_score]]<3),"EXIT",IF(AND(tbl_scenarios[[#This Row],[net_margin_A]]>=0.25,tbl_raw[[#This Row],[avg_review_score]]>=4),"SCALE","OPTIMIZE")) -> OPTIMIZE | J8: =tbl_raw[[#This Row],[gross_revenue]]-tbl_raw[[#This Row],[return_loss]]*(1+scn_B_returns_up/0.05)-tbl_raw[[#This Row],[cogs]]-(tbl_raw[[#This Row],[storage_cost]]+tbl_raw[[#This Row],[fulfillment_cost]]+tbl_raw[[#This Row],[freight_cost]]) -> 6876.2 | K8: =tbl_scenarios[[#This Row],[net_profit_B]]/tbl_raw[[#This Row],[gross_revenue]] -> 0.167375 | L8: =tbl_scenarios[[#This Row],[net_margin_B]]-tbl_scenarios[[#This Row],[net_margin_pct]] -> -0.0060025412 | M8: =IF(OR(tbl_scenarios[[#This Row],[net_margin_B]]<0.1,tbl_raw[[#This Row],[avg_review_score]]<3),"EXIT",IF(AND(tbl_scenarios[[#This Row],[net_margin_B]]>=0.25,tbl_raw[[#This Row],[avg_review_score]]>=4),"SCALE","OPTIMIZE")) -> OPTIMIZE | N8: =tbl_raw[[#This Row],[gross_revenue]]*(1-scn_C_price_down)-tbl_raw[[#This Row],[return_loss]]-tbl_raw[[#This Row],[cogs]]-(tbl_raw[[#This Row],[storage_cost]]+tbl_raw[[#This Row],[fulfillment_cost]]+tbl_raw[[#This Row],[freight_cost]]) -> 5068.67 | O8: =tbl_scenarios[[#This Row],[net_profit_C]]/(tbl_raw[[#This Row],[gross_revenue]]*(1-scn_C_price_down)) -> 0.12987109 | P8: =tbl_scenarios[[#This Row],[net_margin_C]]-tbl_scenarios[[#This Row],[net_margin_pct]] -> -0.043506445 | Q8: =IF(OR(tbl_scenarios[[#This Row],[net_margin_C]]<0.1,tbl_raw[[#This Row],[avg_review_score]]<3),"EXIT",IF(AND(tbl_scenarios[[#This Row],[net_margin_C]]>=0.25,tbl_raw[[#This Row],[avg_review_score]]>=4),"SCALE","OPTIMIZE")) -> OPTIMIZE | R8: =IF(OR(tbl_scenarios[[#This Row],[decision_A]]<>tbl_scenarios[[#This Row],[decision]],tbl_scenarios[[#This Row],[decision_B]]<>tbl_scenarios[[#This Row],[decision]],tbl_scenarios[[#This Row],[decision_C]]<>tbl_scenarios[[#This Row],[decision]]),"Decision changes","Stable") -> Stable
A9: =tbl_raw[[#This Row],[product_id]] -> 25c38557cf793876c5abdd5931f922db | B9: =tbl_raw[[#This Row],[category]] -> baby | C9: =tbl_profitability[[#This Row],[net_profit]] -> 20957.94 | D9: =tbl_profitability[[#This Row],[net_margin_pct]] -> 0.53866316 | E9: =tbl_profitability[[#This Row],[decision]] -> EXIT | F9: =tbl_raw[[#This Row],[gross_revenue]]-tbl_raw[[#This Row],[return_loss]]-tbl_raw[[#This Row],[cogs]]*(1+scn_A_cogs_up)-(tbl_raw[[#This Row],[storage_cost]]+tbl_raw[[#This Row],[fulfillment_cost]]+tbl_raw[[#This Row],[freight_cost]]) -> 19323.833 | G9: =tbl_scenarios[[#This Row],[net_profit_A]]/tbl_raw[[#This Row],[gross_revenue]] -> 0.49666317 | H9: =tbl_scenarios[[#This Row],[net_margin_A]]-tbl_scenarios[[#This Row],[net_margin_pct]] -> -0.041999989 | I9: =IF(OR(tbl_scenarios[[#This Row],[net_margin_A]]<0.1,tbl_raw[[#This Row],[avg_review_score]]<3),"EXIT",IF(AND(tbl_scenarios[[#This Row],[net_margin_A]]>=0.25,tbl_raw[[#This Row],[avg_review_score]]>=4),"SCALE","OPTIMIZE")) -> EXIT | J9: =tbl_raw[[#This Row],[gross_revenue]]-tbl_raw[[#This Row],[return_loss]]*(1+scn_B_returns_up/0.05)-tbl_raw[[#This Row],[cogs]]-(tbl_raw[[#This Row],[storage_cost]]+tbl_raw[[#This Row],[fulfillment_cost]]+tbl_raw[[#This Row],[freight_cost]]) -> 20944.26 | K9: =tbl_scenarios[[#This Row],[net_profit_B]]/tbl_raw[[#This Row],[gross_revenue]] -> 0.53831156 | L9: =tbl_scenarios[[#This Row],[net_margin_B]]-tbl_scenarios[[#This Row],[net_margin_pct]] -> -0.00035160479 | M9: =IF(OR(tbl_scenarios[[#This Row],[net_margin_B]]<0.1,tbl_raw[[#This Row],[avg_review_score]]<3),"EXIT",IF(AND(tbl_scenarios[[#This Row],[net_margin_B]]>=0.25,tbl_raw[[#This Row],[avg_review_score]]>=4),"SCALE","OPTIMIZE")) -> EXIT | N9: =tbl_raw[[#This Row],[gross_revenue]]*(1-scn_C_price_down)-tbl_raw[[#This Row],[return_loss]]-tbl_raw[[#This Row],[cogs]]-(tbl_raw[[#This Row],[storage_cost]]+tbl_raw[[#This Row],[fulfillment_cost]]+tbl_raw[[#This Row],[freight_cost]]) -> 19012.574 | O9: =tbl_scenarios[[#This Row],[net_profit_C]]/(tbl_raw[[#This Row],[gross_revenue]]*(1-scn_C_price_down)) -> 0.51438228 | P9: =tbl_scenarios[[#This Row],[net_margin_C]]-tbl_scenarios[[#This Row],[net_margin_pct]] -> -0.024280886 | Q9: =IF(OR(tbl_scenarios[[#This Row],[net_margin_C]]<0.1,tbl_raw[[#This Row],[avg_review_score]]<3),"EXIT",IF(AND(tbl_scenarios[[#This Row],[net_margin_C]]>=0.25,tbl_raw[[#This Row],[avg_review_score]]>=4),"SCALE","OPTIMIZE")) -> EXIT | R9: =IF(OR(tbl_scenarios[[#This Row],[decision_A]]<>tbl_scenarios[[#This Row],[decision]],tbl_scenarios[[#This Row],[decision_B]]<>tbl_scenarios[[#This Row],[decision]],tbl_scenarios[[#This Row],[decision_C]]<>tbl_scenarios[[#This Row],[decision]]),"Decision changes","Stable") -> Stable
A10: =tbl_raw[[#This Row],[product_id]] -> 5f504b3a1c75b73d6151be81eb05bdc9 | B10: =tbl_raw[[#This Row],[category]] -> cool_stuff | C10: =tbl_profitability[[#This Row],[net_profit]] -> 16424.05 | D10: =tbl_profitability[[#This Row],[net_margin_pct]] -> 0.43525981 | E10: =tbl_profitability[[#This Row],[decision]] -> SCALE | F10: =tbl_raw[[#This Row],[gross_revenue]]-tbl_raw[[#This Row],[return_loss]]-tbl_raw[[#This Row],[cogs]]*(1+scn_A_cogs_up)-(tbl_raw[[#This Row],[storage_cost]]+tbl_raw[[#This Row],[fulfillment_cost]]+tbl_raw[[#This Row],[freight_cost]]) -> 14726.024 | G10: =tbl_scenarios[[#This Row],[net_profit_A]]/tbl_raw[[#This Row],[gross_revenue]] -> 0.39025979 | H10: =tbl_scenarios[[#This Row],[net_margin_A]]-tbl_scenarios[[#This Row],[net_margin_pct]] -> -0.045000013 | I10: =IF(OR(tbl_scenarios[[#This Row],[net_margin_A]]<0.1,tbl_raw[[#This Row],[avg_review_score]]<3),"EXIT",IF(AND(tbl_scenarios[[#This Row],[net_margin_A]]>=0.25,tbl_raw[[#This Row],[avg_review_score]]>=4),"SCALE","OPTIMIZE")) -> SCALE | J10: =tbl_raw[[#This Row],[gross_revenue]]-tbl_raw[[#This Row],[return_loss]]*(1+scn_B_returns_up/0.05)-tbl_raw[[#This Row],[cogs]]-(tbl_raw[[#This Row],[storage_cost]]+tbl_raw[[#This Row],[fulfillment_cost]]+tbl_raw[[#This Row],[freight_cost]]) -> 16401.37 | K10: =tbl_scenarios[[#This Row],[net_profit_B]]/tbl_raw[[#This Row],[gross_revenue]] -> 0.43465876 | L10: =tbl_scenarios[[#This Row],[net_margin_B]]-tbl_scenarios[[#This Row],[net_margin_pct]] -> -0.00060105104 | M10: =IF(OR(tbl_scenarios[[#This Row],[net_margin_B]]<0.1,tbl_raw[[#This Row],[avg_review_score]]<3),"EXIT",IF(AND(tbl_scenarios[[#This Row],[net_margin_B]]>=0.25,tbl_raw[[#This Row],[avg_review_score]]>=4),"SCALE","OPTIMIZE")) -> SCALE | N10: =tbl_raw[[#This Row],[gross_revenue]]*(1-scn_C_price_down)-tbl_raw[[#This Row],[return_loss]]-tbl_raw[[#This Row],[cogs]]-(tbl_raw[[#This Row],[storage_cost]]+tbl_raw[[#This Row],[fulfillment_cost]]+tbl_raw[[#This Row],[freight_cost]]) -> 14537.355 | O10: =tbl_scenarios[[#This Row],[net_profit_C]]/(tbl_raw[[#This Row],[gross_revenue]]*(1-scn_C_price_down)) -> 0.40553664 | P10: =tbl_scenarios[[#This Row],[net_margin_C]]-tbl_scenarios[[#This Row],[net_margin_pct]] -> -0.029723168 | Q10: =IF(OR(tbl_scenarios[[#This Row],[net_margin_C]]<0.1,tbl_raw[[#This Row],[avg_review_score]]<3),"EXIT",IF(AND(tbl_scenarios[[#This Row],[net_margin_C]]>=0.25,tbl_raw[[#This Row],[avg_review_score]]>=4),"SCALE","OPTIMIZE")) -> SCALE | R10: =IF(OR(tbl_scenarios[[#This Row],[decision_A]]<>tbl_scenarios[[#This Row],[decision]],tbl_scenarios[[#This Row],[decision_B]]<>tbl_scenarios[[#This Row],[decision]],tbl_scenarios[[#This Row],[decision_C]]<>tbl_scenarios[[#This Row],[decision]]),"Decision changes","Stable") -> Stable
A11: =tbl_raw[[#This Row],[product_id]] -> 53b36df67ebb7c41585e8d54d6772e08 | B11: =tbl_raw[[#This Row],[category]] -> watches_gifts | C11: =tbl_profitability[[#This Row],[net_profit]] -> 17918.59 | D11: =tbl_profitability[[#This Row],[net_margin_pct]] -> 0.47550328 | E11: =tbl_profitability[[#This Row],[decision]] -> SCALE | F11: =tbl_raw[[#This Row],[gross_revenue]]-tbl_raw[[#This Row],[return_loss]]-tbl_raw[[#This Row],[cogs]]*(1+scn_A_cogs_up)-(tbl_raw[[#This Row],[storage_cost]]+tbl_raw[[#This Row],[fulfillment_cost]]+tbl_raw[[#This Row],[freight_cost]]) -> 16335.886 | G11: =tbl_scenarios[[#This Row],[net_profit_A]]/tbl_raw[[#This Row],[gross_revenue]] -> 0.43350328 | H11: =tbl_scenarios[[#This Row],[net_margin_A]]-tbl_scenarios[[#This Row],[net_margin_pct]] -> -0.04200001 | I11: =IF(OR(tbl_scenarios[[#This Row],[net_margin_A]]<0.1,tbl_raw[[#This Row],[avg_review_score]]<3),"EXIT",IF(AND(tbl_scenarios[[#This Row],[net_margin_A]]>=0.25,tbl_raw[[#This Row],[avg_review_score]]>=4),"SCALE","OPTIMIZE")) -> SCALE | J11: =tbl_raw[[#This Row],[gross_revenue]]-tbl_raw[[#This Row],[return_loss]]*(1+scn_B_returns_up/0.05)-tbl_raw[[#This Row],[cogs]]-(tbl_raw[[#This Row],[storage_cost]]+tbl_raw[[#This Row],[fulfillment_cost]]+tbl_raw[[#This Row],[freight_cost]]) -> 17802.31 | K11: =tbl_scenarios[[#This Row],[net_profit_B]]/tbl_raw[[#This Row],[gross_revenue]] -> 0.47241758 | L11: =tbl_scenarios[[#This Row],[net_margin_B]]-tbl_scenarios[[#This Row],[net_margin_pct]] -> -0.0030857072 | M11: =IF(OR(tbl_scenarios[[#This Row],[net_margin_B]]<0.1,tbl_raw[[#This Row],[avg_review_score]]<3),"EXIT",IF(AND(tbl_scenarios[[#This Row],[net_margin_B]]>=0.25,tbl_raw[[#This Row],[avg_review_score]]>=4),"SCALE","OPTIMIZE")) -> SCALE | N11: =tbl_raw[[#This Row],[gross_revenue]]*(1-scn_C_price_down)-tbl_raw[[#This Row],[return_loss]]-tbl_raw[[#This Row],[cogs]]-(tbl_raw[[#This Row],[storage_cost]]+tbl_raw[[#This Row],[fulfillment_cost]]+tbl_raw[[#This Row],[freight_cost]]) -> 16034.419 | O11: =tbl_scenarios[[#This Row],[net_profit_C]]/(tbl_raw[[#This Row],[gross_revenue]]*(1-scn_C_price_down)) -> 0.44789819 | P11: =tbl_scenarios[[#This Row],[net_margin_C]]-tbl_scenarios[[#This Row],[net_margin_pct]] -> -0.02760509 | Q11: =IF(OR(tbl_scenarios[[#This Row],[net_margin_C]]<0.1,tbl_raw[[#This Row],[avg_review_score]]<3),"EXIT",IF(AND(tbl_scenarios[[#This Row],[net_margin_C]]>=0.25,tbl_raw[[#This Row],[avg_review_score]]>=4),"SCALE","OPTIMIZE")) -> SCALE | R11: =IF(OR(tbl_scenarios[[#This Row],[decision_A]]<>tbl_scenarios[[#This Row],[decision]],tbl_scenarios[[#This Row],[decision_B]]<>tbl_scenarios[[#This Row],[decision]],tbl_scenarios[[#This Row],[decision_C]]<>tbl_scenarios[[#This Row],[decision]]),"Decision changes","Stable") -> Stable
A12: =tbl_raw[[#This Row],[product_id]] -> aca2eb7d00ea1a7b8ebd4e68314663af | B12: =tbl_raw[[#This Row],[category]] -> furniture_decor | C12: =tbl_profitability[[#This Row],[net_profit]] -> 6338.31 | D12: =tbl_profitability[[#This Row],[net_margin_pct]] -> 0.16853218 | E12: =tbl_profitability[[#This Row],[decision]] -> OPTIMIZE | F12: =tbl_raw[[#This Row],[gross_revenue]]-tbl_raw[[#This Row],[return_loss]]-tbl_raw[[#This Row],[cogs]]*(1+scn_A_cogs_up)-(tbl_raw[[#This Row],[storage_cost]]+tbl_raw[[#This Row],[fulfillment_cost]]+tbl_raw[[#This Row],[freight_cost]]) -> 4645.909 | G12: =tbl_scenarios[[#This Row],[net_profit_A]]/tbl_raw[[#This Row],[gross_revenue]] -> 0.12353217 | H12: =tbl_scenarios[[#This Row],[net_margin_A]]-tbl_scenarios[[#This Row],[net_margin_pct]] -> -0.045000013 | I12: =IF(OR(tbl_scenarios[[#This Row],[net_margin_A]]<0.1,tbl_raw[[#This Row],[avg_review_score]]<3),"EXIT",IF(AND(tbl_scenarios[[#This Row],[net_margin_A]]>=0.25,tbl_raw[[#This Row],[avg_review_score]]>=4),"SCALE","OPTIMIZE")) -> OPTIMIZE | J12: =tbl_raw[[#This Row],[gross_revenue]]-tbl_raw[[#This Row],[return_loss]]*(1+scn_B_returns_up/0.05)-tbl_raw[[#This Row],[cogs]]-(tbl_raw[[#This Row],[storage_cost]]+tbl_raw[[#This Row],[fulfillment_cost]]+tbl_raw[[#This Row],[freight_cost]]) -> 6148.59 | K12: =tbl_scenarios[[#This Row],[net_profit_B]]/tbl_raw[[#This Row],[gross_revenue]] -> 0.16348763 | L12: =tbl_scenarios[[#This Row],[net_margin_B]]-tbl_scenarios[[#This Row],[net_margin_pct]] -> -0.0050445506 | M12: =IF(OR(tbl_scenarios[[#This Row],[net_margin_B]]<0.1,tbl_raw[[#This Row],[avg_review_score]]<3),"EXIT",IF(AND(tbl_scenarios[[#This Row],[net_margin_B]]>=0.25,tbl_raw[[#This Row],[avg_review_score]]>=4),"SCALE","OPTIMIZE")) -> OPTIMIZE | N12: =tbl_raw[[#This Row],[gross_revenue]]*(1-scn_C_price_down)-tbl_raw[[#This Row],[return_loss]]-tbl_raw[[#This Row],[cogs]]-(tbl_raw[[#This Row],[storage_cost]]+tbl_raw[[#This Row],[fulfillment_cost]]+tbl_raw[[#This Row],[freight_cost]]) -> 4457.865 | O12: =tbl_scenarios[[#This Row],[net_profit_C]]/(tbl_raw[[#This Row],[gross_revenue]]*(1-scn_C_price_down)) -> 0.12477072 | P12: =tbl_scenarios[[#This Row],[net_margin_C]]-tbl_scenarios[[#This Row],[net_margin_pct]] -> -0.043761464 | Q12: =IF(OR(tbl_scenarios[[#This Row],[net_margin_C]]<0.1,tbl_raw[[#This Row],[avg_review_score]]<3),"EXIT",IF(AND(tbl_scenarios[[#This Row],[net_margin_C]]>=0.25,tbl_raw[[#This Row],[avg_review_score]]>=4),"SCALE","OPTIMIZE")) -> OPTIMIZE | R12: =IF(OR(tbl_scenarios[[#This Row],[decision_A]]<>tbl_scenarios[[#This Row],[decision]],tbl_scenarios[[#This Row],[decision_B]]<>tbl_scenarios[[#This Row],[decision]],tbl_scenarios[[#This Row],[decision_C]]<>tbl_scenarios[[#This Row],[decision]]),"Decision changes","Stable") -> Stable
A13: =tbl_raw[[#This Row],[product_id]] -> e0d64dcfaa3b6db5c54ca298ae101d05 | B13: =tbl_raw[[#This Row],[category]] -> watches_gifts | C13: =tbl_profitability[[#This Row],[net_profit]] -> 13839.25 | D13: =tbl_profitability[[#This Row],[net_margin_pct]] -> 0.43537699 | E13: =tbl_profitability[[#This Row],[decision]] -> OPTIMIZE | F13: =tbl_raw[[#This Row],[gross_revenue]]-tbl_raw[[#This Row],[return_loss]]-tbl_raw[[#This Row],[cogs]]*(1+scn_A_cogs_up)-(tbl_raw[[#This Row],[storage_cost]]+tbl_raw[[#This Row],[fulfillment_cost]]+tbl_raw[[#This Row],[freight_cost]]) -> 12504.204 | G13: =tbl_scenarios[[#This Row],[net_profit_A]]/tbl_raw[[#This Row],[gross_revenue]] -> 0.393377 | H13: =tbl_scenarios[[#This Row],[net_margin_A]]-tbl_scenarios[[#This Row],[net_margin_pct]] -> -0.041999986 | I13: =IF(OR(tbl_scenarios[[#This Row],[net_margin_A]]<0.1,tbl_raw[[#This Row],[avg_review_score]]<3),"EXIT",IF(AND(tbl_scenarios[[#This Row],[net_margin_A]]>=0.25,tbl_raw[[#This Row],[avg_review_score]]>=4),"SCALE","OPTIMIZE")) -> OPTIMIZE | J13: =tbl_raw[[#This Row],[gross_revenue]]-tbl_raw[[#This Row],[return_loss]]*(1+scn_B_returns_up/0.05)-tbl_raw[[#This Row],[cogs]]-(tbl_raw[[#This Row],[storage_cost]]+tbl_raw[[#This Row],[fulfillment_cost]]+tbl_raw[[#This Row],[freight_cost]]) -> 13769.41 | K13: =tbl_scenarios[[#This Row],[net_profit_B]]/tbl_raw[[#This Row],[gross_revenue]] -> 0.43317985 | L13: =tbl_scenarios[[#This Row],[net_margin_B]]-tbl_scenarios[[#This Row],[net_margin_pct]] -> -0.0021971371 | M13: =IF(OR(tbl_scenarios[[#This Row],[net_margin_B]]<0.1,tbl_raw[[#This Row],[avg_review_score]]<3),"EXIT",IF(AND(tbl_scenarios[[#This Row],[net_margin_B]]>=0.25,tbl_raw[[#This Row],[avg_review_score]]>=4),"SCALE","OPTIMIZE")) -> OPTIMIZE | N13: =tbl_raw[[#This Row],[gross_revenue]]*(1-scn_C_price_down)-tbl_raw[[#This Row],[return_loss]]-tbl_raw[[#This Row],[cogs]]-(tbl_raw[[#This Row],[storage_cost]]+tbl_raw[[#This Row],[fulfillment_cost]]+tbl_raw[[#This Row],[freight_cost]]) -> 12249.909 | O13: =tbl_scenarios[[#This Row],[net_profit_C]]/(tbl_raw[[#This Row],[gross_revenue]]*(1-scn_C_price_down)) -> 0.40565999 | P13: =tbl_scenarios[[#This Row],[net_margin_C]]-tbl_scenarios[[#This Row],[net_margin_pct]] -> -0.029717001 | Q13: =IF(OR(tbl_scenarios[[#This Row],[net_margin_C]]<0.1,tbl_raw[[#This Row],[avg_review_score]]<3),"EXIT",IF(AND(tbl_scenarios[[#This Row],[net_margin_C]]>=0.25,tbl_raw[[#This Row],[avg_review_score]]>=4),"SCALE","OPTIMIZE")) -> OPTIMIZE | R13: =IF(OR(tbl_scenarios[[#This Row],[decision_A]]<>tbl_scenarios[[#This Row],[decision]],tbl_scenarios[[#This Row],[decision_B]]<>tbl_scenarios[[#This Row],[decision]],tbl_scenarios[[#This Row],[decision_C]]<>tbl_scenarios[[#This Row],[decision]]),"Decision changes","Stable") -> Stable
A14: =tbl_raw[[#This Row],[product_id]] -> d285360f29ac7fd97640bf0baef03de0 | B14: =tbl_raw[[#This Row],[category]] -> watches_gifts | C14: =tbl_profitability[[#This Row],[net_profit]] -> 15702.77 | D14: =tbl_profitability[[#This Row],[net_margin_pct]] -> 0.49654896 | E14: =tbl_profitability[[#This Row],[decision]] -> OPTIMIZE | F14: =tbl_raw[[#This Row],[gross_revenue]]-tbl_raw[[#This Row],[return_loss]]-tbl_raw[[#This Row],[cogs]]*(1+scn_A_cogs_up)-(tbl_raw[[#This Row],[storage_cost]]+tbl_raw[[#This Row],[fulfillment_cost]]+tbl_raw[[#This Row],[freight_cost]]) -> 14374.57 | G14: =tbl_scenarios[[#This Row],[net_profit_A]]/tbl_raw[[#This Row],[gross_revenue]] -> 0.45454896 | H14: =tbl_scenarios[[#This Row],[net_margin_A]]-tbl_scenarios[[#This Row],[net_margin_pct]] -> -0.041999999 | I14: =IF(OR(tbl_scenarios[[#This Row],[net_margin_A]]<0.1,tbl_raw[[#This Row],[avg_review_score]]<3),"EXIT",IF(AND(tbl_scenarios[[#This Row],[net_margin_A]]>=0.25,tbl_raw[[#This Row],[avg_review_score]]>=4),"SCALE","OPTIMIZE")) -> OPTIMIZE | J14: =tbl_raw[[#This Row],[gross_revenue]]-tbl_raw[[#This Row],[return_loss]]*(1+scn_B_returns_up/0.05)-tbl_raw[[#This Row],[cogs]]-(tbl_raw[[#This Row],[storage_cost]]+tbl_raw[[#This Row],[fulfillment_cost]]+tbl_raw[[#This Row],[freight_cost]]) -> 15658.49 | K14: =tbl_scenarios[[#This Row],[net_profit_B]]/tbl_raw[[#This Row],[gross_revenue]] -> 0.49514875 | L14: =tbl_scenarios[[#This Row],[net_margin_B]]-tbl_scenarios[[#This Row],[net_margin_pct]] -> -0.0014002108 | M14: =IF(OR(tbl_scenarios[[#This Row],[net_margin_B]]<0.1,tbl_raw[[#This Row],[avg_review_score]]<3),"EXIT",IF(AND(tbl_scenarios[[#This Row],[net_margin_B]]>=0.25,tbl_raw[[#This Row],[avg_review_score]]>=4),"SCALE","OPTIMIZE")) -> OPTIMIZE | N14: =tbl_raw[[#This Row],[gross_revenue]]*(1-scn_C_price_down)-tbl_raw[[#This Row],[return_loss]]-tbl_raw[[#This Row],[cogs]]-(tbl_raw[[#This Row],[storage_cost]]+tbl_raw[[#This Row],[fulfillment_cost]]+tbl_raw[[#This Row],[freight_cost]]) -> 14121.58 | O14: =tbl_scenarios[[#This Row],[net_profit_C]]/(tbl_raw[[#This Row],[gross_revenue]]*(1-scn_C_price_down)) -> 0.47005154 | P14: =tbl_scenarios[[#This Row],[net_margin_C]]-tbl_scenarios[[#This Row],[net_margin_pct]] -> -0.026497423 | Q14: =IF(OR(tbl_scenarios[[#This Row],[net_margin_C]]<0.1,tbl_raw[[#This Row],[avg_review_score]]<3),"EXIT",IF(AND(tbl_scenarios[[#This Row],[net_margin_C]]>=0.25,tbl_raw[[#This Row],[avg_review_score]]>=4),"SCALE","OPTIMIZE")) -> OPTIMIZE | R14: =IF(OR(tbl_scenarios[[#This Row],[decision_A]]<>tbl_scenarios[[#This Row],[decision]],tbl_scenarios[[#This Row],[decision_B]]<>tbl_scenarios[[#This Row],[decision]],tbl_scenarios[[#This Row],[decision_C]]<>tbl_scenarios[[#This Row],[decision]]),"Decision changes","Stable") -> Stable
A15: =tbl_raw[[#This Row],[product_id]] -> 7a10781637204d8d10485c71a6108a2e | B15: =tbl_raw[[#This Row],[category]] -> watches_gifts | C15: =tbl_profitability[[#This Row],[net_profit]] -> 14585.43 | D15: =tbl_profitability[[#This Row],[net_margin_pct]] -> 0.47872093 | E15: =tbl_profitability[[#This Row],[decision]] -> SCALE | F15: =tbl_raw[[#This Row],[gross_revenue]]-tbl_raw[[#This Row],[return_loss]]-tbl_raw[[#This Row],[cogs]]*(1+scn_A_cogs_up)-(tbl_raw[[#This Row],[storage_cost]]+tbl_raw[[#This Row],[fulfillment_cost]]+tbl_raw[[#This Row],[freight_cost]]) -> 13305.795 | G15: =tbl_scenarios[[#This Row],[net_profit_A]]/tbl_raw[[#This Row],[gross_revenue]] -> 0.43672093 | H15: =tbl_scenarios[[#This Row],[net_margin_A]]-tbl_scenarios[[#This Row],[net_margin_pct]] -> -0.042 | I15: =IF(OR(tbl_scenarios[[#This Row],[net_margin_A]]<0.1,tbl_raw[[#This Row],[avg_review_score]]<3),"EXIT",IF(AND(tbl_scenarios[[#This Row],[net_margin_A]]>=0.25,tbl_raw[[#This Row],[avg_review_score]]>=4),"SCALE","OPTIMIZE")) -> SCALE | J15: =tbl_raw[[#This Row],[gross_revenue]]-tbl_raw[[#This Row],[return_loss]]*(1+scn_B_returns_up/0.05)-tbl_raw[[#This Row],[cogs]]-(tbl_raw[[#This Row],[storage_cost]]+tbl_raw[[#This Row],[fulfillment_cost]]+tbl_raw[[#This Row],[freight_cost]]) -> 14533.95 | K15: =tbl_scenarios[[#This Row],[net_profit_B]]/tbl_raw[[#This Row],[gross_revenue]] -> 0.47703126 | L15: =tbl_scenarios[[#This Row],[net_margin_B]]-tbl_scenarios[[#This Row],[net_margin_pct]] -> -0.0016896693 | M15: =IF(OR(tbl_scenarios[[#This Row],[net_margin_B]]<0.1,tbl_raw[[#This Row],[avg_review_score]]<3),"EXIT",IF(AND(tbl_scenarios[[#This Row],[net_margin_B]]>=0.25,tbl_raw[[#This Row],[avg_review_score]]>=4),"SCALE","OPTIMIZE")) -> SCALE | N15: =tbl_raw[[#This Row],[gross_revenue]]*(1-scn_C_price_down)-tbl_raw[[#This Row],[return_loss]]-tbl_raw[[#This Row],[cogs]]-(tbl_raw[[#This Row],[storage_cost]]+tbl_raw[[#This Row],[fulfillment_cost]]+tbl_raw[[#This Row],[freight_cost]]) -> 13062.055 | O15: =tbl_scenarios[[#This Row],[net_profit_C]]/(tbl_raw[[#This Row],[gross_revenue]]*(1-scn_C_price_down)) -> 0.45128519 | P15: =tbl_scenarios[[#This Row],[net_margin_C]]-tbl_scenarios[[#This Row],[net_margin_pct]] -> -0.02743574 | Q15: =IF(OR(tbl_scenarios[[#This Row],[net_margin_C]]<0.1,tbl_raw[[#This Row],[avg_review_score]]<3),"EXIT",IF(AND(tbl_scenarios[[#This Row],[net_margin_C]]>=0.25,tbl_raw[[#This Row],[avg_review_score]]>=4),"SCALE","OPTIMIZE")) -> SCALE | R15: =IF(OR(tbl_scenarios[[#This Row],[decision_A]]<>tbl_scenarios[[#This Row],[decision]],tbl_scenarios[[#This Row],[decision_B]]<>tbl_scenarios[[#This Row],[decision]],tbl_scenarios[[#This Row],[decision_C]]<>tbl_scenarios[[#This Row],[decision]]),"Decision changes","Stable") -> Stable
A16: =tbl_raw[[#This Row],[product_id]] -> f1c7f353075ce59d8a6f3cf58f419c9c | B16: =tbl_raw[[#This Row],[category]] -> bed_bath_table | C16: =tbl_profitability[[#This Row],[net_profit]] -> 11802.21 | D16: =tbl_profitability[[#This Row],[net_margin_pct]] -> 0.39344162 | E16: =tbl_profitability[[#This Row],[decision]] -> SCALE | F16: =tbl_raw[[#This Row],[gross_revenue]]-tbl_raw[[#This Row],[return_loss]]-tbl_raw[[#This Row],[cogs]]*(1+scn_A_cogs_up)-(tbl_raw[[#This Row],[storage_cost]]+tbl_raw[[#This Row],[fulfillment_cost]]+tbl_raw[[#This Row],[freight_cost]]) -> 10452.329 | G16: =tbl_scenarios[[#This Row],[net_profit_A]]/tbl_raw[[#This Row],[gross_revenue]] -> 0.34844163 | H16: =tbl_scenarios[[#This Row],[net_margin_A]]-tbl_scenarios[[#This Row],[net_margin_pct]] -> -0.044999993 | I16: =IF(OR(tbl_scenarios[[#This Row],[net_margin_A]]<0.1,tbl_raw[[#This Row],[avg_review_score]]<3),"EXIT",IF(AND(tbl_scenarios[[#This Row],[net_margin_A]]>=0.25,tbl_raw[[#This Row],[avg_review_score]]>=4),"SCALE","OPTIMIZE")) -> SCALE | J16: =tbl_raw[[#This Row],[gross_revenue]]-tbl_raw[[#This Row],[return_loss]]*(1+scn_B_returns_up/0.05)-tbl_raw[[#This Row],[cogs]]-(tbl_raw[[#This Row],[storage_cost]]+tbl_raw[[#This Row],[fulfillment_cost]]+tbl_raw[[#This Row],[freight_cost]]) -> 11746.77 | K16: =tbl_scenarios[[#This Row],[net_profit_B]]/tbl_raw[[#This Row],[gross_revenue]] -> 0.39159346 | L16: =tbl_scenarios[[#This Row],[net_margin_B]]-tbl_scenarios[[#This Row],[net_margin_pct]] -> -0.0018481626 | M16: =IF(OR(tbl_scenarios[[#This Row],[net_margin_B]]<0.1,tbl_raw[[#This Row],[avg_review_score]]<3),"EXIT",IF(AND(tbl_scenarios[[#This Row],[net_margin_B]]>=0.25,tbl_raw[[#This Row],[avg_review_score]]>=4),"SCALE","OPTIMIZE")) -> SCALE | N16: =tbl_raw[[#This Row],[gross_revenue]]*(1-scn_C_price_down)-tbl_raw[[#This Row],[return_loss]]-tbl_raw[[#This Row],[cogs]]-(tbl_raw[[#This Row],[storage_cost]]+tbl_raw[[#This Row],[fulfillment_cost]]+tbl_raw[[#This Row],[freight_cost]]) -> 10302.342 | O16: =tbl_scenarios[[#This Row],[net_profit_C]]/(tbl_raw[[#This Row],[gross_revenue]]*(1-scn_C_price_down)) -> 0.3615175 | P16: =tbl_scenarios[[#This Row],[net_margin_C]]-tbl_scenarios[[#This Row],[net_margin_pct]] -> -0.031924125 | Q16: =IF(OR(tbl_scenarios[[#This Row],[net_margin_C]]<0.1,tbl_raw[[#This Row],[avg_review_score]]<3),"EXIT",IF(AND(tbl_scenarios[[#This Row],[net_margin_C]]>=0.25,tbl_raw[[#This Row],[avg_review_score]]>=4),"SCALE","OPTIMIZE")) -> SCALE | R16: =IF(OR(tbl_scenarios[[#This Row],[decision_A]]<>tbl_scenarios[[#This Row],[decision]],tbl_scenarios[[#This Row],[decision_B]]<>tbl_scenarios[[#This Row],[decision]],tbl_scenarios[[#This Row],[decision_C]]<>tbl_scenarios[[#This Row],[decision]]),"Decision changes","Stable") -> Stable
